[2021-09-07 01:09:58,960] {taskinstance.py:903} INFO - Dependencies all met for <TaskInstance: users_and_posts_etl_dag.load_data 2021-09-07T01:09:56.735031+00:00 [queued]>
[2021-09-07 01:09:58,968] {taskinstance.py:903} INFO - Dependencies all met for <TaskInstance: users_and_posts_etl_dag.load_data 2021-09-07T01:09:56.735031+00:00 [queued]>
[2021-09-07 01:09:58,968] {taskinstance.py:1094} INFO - 
--------------------------------------------------------------------------------
[2021-09-07 01:09:58,968] {taskinstance.py:1095} INFO - Starting attempt 1 of 1
[2021-09-07 01:09:58,968] {taskinstance.py:1096} INFO - 
--------------------------------------------------------------------------------
[2021-09-07 01:09:58,979] {taskinstance.py:1114} INFO - Executing <Task(PythonOperator): load_data> on 2021-09-07T01:09:56.735031+00:00
[2021-09-07 01:09:58,982] {standard_task_runner.py:52} INFO - Started process 1776 to run task
[2021-09-07 01:09:58,984] {standard_task_runner.py:76} INFO - Running: ['***', 'tasks', 'run', 'users_and_posts_etl_dag', 'load_data', '2021-09-07T01:09:56.735031+00:00', '--job-id', '66', '--pool', 'default_pool', '--raw', '--subdir', 'DAGS_FOLDER/hoverstate_etl.py', '--cfg-path', '/tmp/tmpl12iqr_9', '--error-file', '/tmp/tmp_a8cxy0m']
[2021-09-07 01:09:58,984] {standard_task_runner.py:77} INFO - Job 66: Subtask load_data
[2021-09-07 01:09:59,013] {logging_mixin.py:109} INFO - Running <TaskInstance: users_and_posts_etl_dag.load_data 2021-09-07T01:09:56.735031+00:00 [running]> on host 731700afc5ff
[2021-09-07 01:09:59,143] {taskinstance.py:1251} INFO - Exporting the following env vars:
AIRFLOW_CTX_DAG_OWNER=***
AIRFLOW_CTX_DAG_ID=users_and_posts_etl_dag
AIRFLOW_CTX_TASK_ID=load_data
AIRFLOW_CTX_EXECUTION_DATE=2021-09-07T01:09:56.735031+00:00
AIRFLOW_CTX_DAG_RUN_ID=manual__2021-09-07T01:09:56.735031+00:00
[2021-09-07 01:09:59,171] {taskinstance.py:1462} ERROR - Task failed with exception
Traceback (most recent call last):
  File "/home/airflow/.local/lib/python3.8/site-packages/airflow/models/taskinstance.py", line 1164, in _run_raw_task
    self._prepare_and_execute_task_with_callbacks(context, task)
  File "/home/airflow/.local/lib/python3.8/site-packages/airflow/models/taskinstance.py", line 1282, in _prepare_and_execute_task_with_callbacks
    result = self._execute_task(context, task_copy)
  File "/home/airflow/.local/lib/python3.8/site-packages/airflow/models/taskinstance.py", line 1312, in _execute_task
    result = task_copy.execute(context=context)
  File "/home/airflow/.local/lib/python3.8/site-packages/airflow/operators/python.py", line 150, in execute
    return_value = self.execute_callable()
  File "/home/airflow/.local/lib/python3.8/site-packages/airflow/operators/python.py", line 161, in execute_callable
    return self.python_callable(*self.op_args, **self.op_kwargs)
  File "/opt/airflow/dags/hoverstate_etl.py", line 90, in load_data
    execute_load(pg_hook, "users", users_path)
  File "/opt/airflow/dags/hoverstate_etl.py", line 150, in execute_load
    pg_hook.copy_expert(query, file_path)
  File "/home/airflow/.local/lib/python3.8/site-packages/airflow/providers/postgres/hooks/postgres.py", line 134, in copy_expert
    with closing(self.get_conn()) as conn:
  File "/home/airflow/.local/lib/python3.8/site-packages/airflow/providers/postgres/hooks/postgres.py", line 88, in get_conn
    conn = deepcopy(self.connection or self.get_connection(conn_id))
  File "/home/airflow/.local/lib/python3.8/site-packages/airflow/hooks/base.py", line 68, in get_connection
    conn = Connection.get_connection_from_secrets(conn_id)
  File "/home/airflow/.local/lib/python3.8/site-packages/airflow/models/connection.py", line 379, in get_connection_from_secrets
    raise AirflowNotFoundException(f"The conn_id `{conn_id}` isn't defined")
airflow.exceptions.AirflowNotFoundException: The conn_id `etl_id` isn't defined
[2021-09-07 01:09:59,174] {taskinstance.py:1505} INFO - Marking task as FAILED. dag_id=users_and_posts_etl_dag, task_id=load_data, execution_date=20210907T010956, start_date=20210907T010958, end_date=20210907T010959
[2021-09-07 01:09:59,197] {local_task_job.py:151} INFO - Task exited with return code 1
[2021-09-07 01:09:59,215] {local_task_job.py:261} INFO - 0 downstream tasks scheduled from follow-on schedule check
