[2021-09-07 02:19:43,377] {taskinstance.py:903} INFO - Dependencies all met for <TaskInstance: users_and_posts_etl_dag.load_data 2021-09-07T02:19:41.071497+00:00 [queued]>
[2021-09-07 02:19:43,388] {taskinstance.py:903} INFO - Dependencies all met for <TaskInstance: users_and_posts_etl_dag.load_data 2021-09-07T02:19:41.071497+00:00 [queued]>
[2021-09-07 02:19:43,388] {taskinstance.py:1094} INFO - 
--------------------------------------------------------------------------------
[2021-09-07 02:19:43,388] {taskinstance.py:1095} INFO - Starting attempt 1 of 1
[2021-09-07 02:19:43,389] {taskinstance.py:1096} INFO - 
--------------------------------------------------------------------------------
[2021-09-07 02:19:43,402] {taskinstance.py:1114} INFO - Executing <Task(PythonOperator): load_data> on 2021-09-07T02:19:41.071497+00:00
[2021-09-07 02:19:43,405] {standard_task_runner.py:52} INFO - Started process 8601 to run task
[2021-09-07 02:19:43,407] {standard_task_runner.py:76} INFO - Running: ['***', 'tasks', 'run', 'users_and_posts_etl_dag', 'load_data', '2021-09-07T02:19:41.071497+00:00', '--job-id', '94', '--pool', 'default_pool', '--raw', '--subdir', 'DAGS_FOLDER/hoverstate_etl.py', '--cfg-path', '/tmp/tmphli6z3cv', '--error-file', '/tmp/tmpvdpvknbg']
[2021-09-07 02:19:43,407] {standard_task_runner.py:77} INFO - Job 94: Subtask load_data
[2021-09-07 02:19:43,442] {logging_mixin.py:109} INFO - Running <TaskInstance: users_and_posts_etl_dag.load_data 2021-09-07T02:19:41.071497+00:00 [running]> on host 731700afc5ff
[2021-09-07 02:19:43,489] {taskinstance.py:1251} INFO - Exporting the following env vars:
AIRFLOW_CTX_DAG_OWNER=***
AIRFLOW_CTX_DAG_ID=users_and_posts_etl_dag
AIRFLOW_CTX_TASK_ID=load_data
AIRFLOW_CTX_EXECUTION_DATE=2021-09-07T02:19:41.071497+00:00
AIRFLOW_CTX_DAG_RUN_ID=manual__2021-09-07T02:19:41.071497+00:00
[2021-09-07 02:19:43,499] {base.py:70} INFO - Using connection to: id: etl. Host: 127.0.0.1, Port: None, Schema: hoverstate, Login: ***, Password: ***, extra: {}
[2021-09-07 02:19:43,500] {taskinstance.py:1462} ERROR - Task failed with exception
Traceback (most recent call last):
  File "/home/airflow/.local/lib/python3.8/site-packages/airflow/models/taskinstance.py", line 1164, in _run_raw_task
    self._prepare_and_execute_task_with_callbacks(context, task)
  File "/home/airflow/.local/lib/python3.8/site-packages/airflow/models/taskinstance.py", line 1282, in _prepare_and_execute_task_with_callbacks
    result = self._execute_task(context, task_copy)
  File "/home/airflow/.local/lib/python3.8/site-packages/airflow/models/taskinstance.py", line 1312, in _execute_task
    result = task_copy.execute(context=context)
  File "/home/airflow/.local/lib/python3.8/site-packages/airflow/operators/python.py", line 150, in execute
    return_value = self.execute_callable()
  File "/home/airflow/.local/lib/python3.8/site-packages/airflow/operators/python.py", line 161, in execute_callable
    return self.python_callable(*self.op_args, **self.op_kwargs)
  File "/opt/airflow/dags/hoverstate_etl.py", line 86, in load_data
    conn = pg_hook.get_conn()
  File "/home/airflow/.local/lib/python3.8/site-packages/airflow/providers/postgres/hooks/postgres.py", line 115, in get_conn
    self.conn = psycopg2.connect(**conn_args)
  File "/home/airflow/.local/lib/python3.8/site-packages/psycopg2/__init__.py", line 122, in connect
    conn = _connect(dsn, connection_factory=connection_factory, **kwasync)
psycopg2.OperationalError: could not connect to server: Connection refused
	Is the server running on host "127.0.0.1" and accepting
	TCP/IP connections on port 5432?

[2021-09-07 02:19:43,502] {taskinstance.py:1505} INFO - Marking task as FAILED. dag_id=users_and_posts_etl_dag, task_id=load_data, execution_date=20210907T021941, start_date=20210907T021943, end_date=20210907T021943
[2021-09-07 02:19:43,540] {local_task_job.py:151} INFO - Task exited with return code 1
[2021-09-07 02:19:43,563] {local_task_job.py:261} INFO - 0 downstream tasks scheduled from follow-on schedule check
