[2021-09-07 05:45:59,423] {taskinstance.py:903} INFO - Dependencies all met for <TaskInstance: json_etl_dag.create_tables 2021-09-07T05:45:58.064910+00:00 [queued]>
[2021-09-07 05:45:59,432] {taskinstance.py:903} INFO - Dependencies all met for <TaskInstance: json_etl_dag.create_tables 2021-09-07T05:45:58.064910+00:00 [queued]>
[2021-09-07 05:45:59,432] {taskinstance.py:1094} INFO - 
--------------------------------------------------------------------------------
[2021-09-07 05:45:59,432] {taskinstance.py:1095} INFO - Starting attempt 1 of 1
[2021-09-07 05:45:59,432] {taskinstance.py:1096} INFO - 
--------------------------------------------------------------------------------
[2021-09-07 05:45:59,443] {taskinstance.py:1114} INFO - Executing <Task(PostgresOperator): create_tables> on 2021-09-07T05:45:58.064910+00:00
[2021-09-07 05:45:59,446] {standard_task_runner.py:52} INFO - Started process 28774 to run task
[2021-09-07 05:45:59,448] {standard_task_runner.py:76} INFO - Running: ['***', 'tasks', 'run', 'json_etl_dag', 'create_tables', '2021-09-07T05:45:58.064910+00:00', '--job-id', '213', '--pool', 'default_pool', '--raw', '--subdir', 'DAGS_FOLDER/etl.py', '--cfg-path', '/tmp/tmpusucy2zd', '--error-file', '/tmp/tmp26tt8o25']
[2021-09-07 05:45:59,448] {standard_task_runner.py:77} INFO - Job 213: Subtask create_tables
[2021-09-07 05:45:59,480] {logging_mixin.py:109} INFO - Running <TaskInstance: json_etl_dag.create_tables 2021-09-07T05:45:58.064910+00:00 [running]> on host 731700afc5ff
[2021-09-07 05:45:59,521] {taskinstance.py:1251} INFO - Exporting the following env vars:
AIRFLOW_CTX_DAG_OWNER=***
AIRFLOW_CTX_DAG_ID=json_etl_dag
AIRFLOW_CTX_TASK_ID=create_tables
AIRFLOW_CTX_EXECUTION_DATE=2021-09-07T05:45:58.064910+00:00
AIRFLOW_CTX_DAG_RUN_ID=manual__2021-09-07T05:45:58.064910+00:00
[2021-09-07 05:45:59,521] {postgres.py:68} INFO - Executing: 
            CREATE TABLE IF NOT EXISTS posts (id int, userId int, title text, body text);
            CREATE TABLE IF NOT EXISTS users (id int, name text, username text, email text, address_street text, address_suite text, address_city text, address_zipcode text, address_geo_lat numeric, address_geo_lng numeric, phone text, website text, company_name text, company_catchPhrase text, company_bs text);
            CREATE TABLE users_temp AS SELECT * FROM users WHERE 1=0;
            CREATE TABLE posts_temp AS SELECT * FROM posts WHERE 1=0;
        
[2021-09-07 05:45:59,528] {base.py:70} INFO - Using connection to: id: nickel-aws. Host: nickel.caybmxchvlv1.us-east-1.rds.amazonaws.com, Port: 5432, Schema: , Login: postgres, Password: ***, extra: {}
[2021-09-07 05:46:00,061] {dbapi.py:204} INFO - Running statement: 
            CREATE TABLE IF NOT EXISTS posts (id int, userId int, title text, body text);
            CREATE TABLE IF NOT EXISTS users (id int, name text, username text, email text, address_street text, address_suite text, address_city text, address_zipcode text, address_geo_lat numeric, address_geo_lng numeric, phone text, website text, company_name text, company_catchPhrase text, company_bs text);
            CREATE TABLE users_temp AS SELECT * FROM users WHERE 1=0;
            CREATE TABLE posts_temp AS SELECT * FROM posts WHERE 1=0;
        , parameters: None
[2021-09-07 05:46:00,230] {taskinstance.py:1462} ERROR - Task failed with exception
Traceback (most recent call last):
  File "/home/airflow/.local/lib/python3.8/site-packages/airflow/models/taskinstance.py", line 1164, in _run_raw_task
    self._prepare_and_execute_task_with_callbacks(context, task)
  File "/home/airflow/.local/lib/python3.8/site-packages/airflow/models/taskinstance.py", line 1282, in _prepare_and_execute_task_with_callbacks
    result = self._execute_task(context, task_copy)
  File "/home/airflow/.local/lib/python3.8/site-packages/airflow/models/taskinstance.py", line 1312, in _execute_task
    result = task_copy.execute(context=context)
  File "/home/airflow/.local/lib/python3.8/site-packages/airflow/providers/postgres/operators/postgres.py", line 70, in execute
    self.hook.run(self.sql, self.autocommit, parameters=self.parameters)
  File "/home/airflow/.local/lib/python3.8/site-packages/airflow/hooks/dbapi.py", line 184, in run
    self._run_command(cur, sql_statement, parameters)
  File "/home/airflow/.local/lib/python3.8/site-packages/airflow/hooks/dbapi.py", line 208, in _run_command
    cur.execute(sql_statement)
psycopg2.errors.DuplicateTable: relation "users_temp" already exists

[2021-09-07 05:46:00,232] {taskinstance.py:1505} INFO - Marking task as FAILED. dag_id=json_etl_dag, task_id=create_tables, execution_date=20210907T054558, start_date=20210907T054559, end_date=20210907T054600
[2021-09-07 05:46:00,262] {local_task_job.py:151} INFO - Task exited with return code 1
[2021-09-07 05:46:00,285] {local_task_job.py:261} INFO - 0 downstream tasks scheduled from follow-on schedule check
