[2021-09-07 01:16:32,394] {taskinstance.py:903} INFO - Dependencies all met for <TaskInstance: users_and_posts_etl_dag.load_data 2021-09-07T01:16:30.724298+00:00 [queued]>
[2021-09-07 01:16:32,403] {taskinstance.py:903} INFO - Dependencies all met for <TaskInstance: users_and_posts_etl_dag.load_data 2021-09-07T01:16:30.724298+00:00 [queued]>
[2021-09-07 01:16:32,403] {taskinstance.py:1094} INFO - 
--------------------------------------------------------------------------------
[2021-09-07 01:16:32,403] {taskinstance.py:1095} INFO - Starting attempt 1 of 1
[2021-09-07 01:16:32,403] {taskinstance.py:1096} INFO - 
--------------------------------------------------------------------------------
[2021-09-07 01:16:32,415] {taskinstance.py:1114} INFO - Executing <Task(PythonOperator): load_data> on 2021-09-07T01:16:30.724298+00:00
[2021-09-07 01:16:32,419] {standard_task_runner.py:52} INFO - Started process 2435 to run task
[2021-09-07 01:16:32,421] {standard_task_runner.py:76} INFO - Running: ['***', 'tasks', 'run', 'users_and_posts_etl_dag', 'load_data', '2021-09-07T01:16:30.724298+00:00', '--job-id', '74', '--pool', 'default_pool', '--raw', '--subdir', 'DAGS_FOLDER/hoverstate_etl.py', '--cfg-path', '/tmp/tmpufdby69j', '--error-file', '/tmp/tmpd8xge_lb']
[2021-09-07 01:16:32,422] {standard_task_runner.py:77} INFO - Job 74: Subtask load_data
[2021-09-07 01:16:32,453] {logging_mixin.py:109} INFO - Running <TaskInstance: users_and_posts_etl_dag.load_data 2021-09-07T01:16:30.724298+00:00 [running]> on host 731700afc5ff
[2021-09-07 01:16:32,493] {taskinstance.py:1251} INFO - Exporting the following env vars:
AIRFLOW_CTX_DAG_OWNER=***
AIRFLOW_CTX_DAG_ID=users_and_posts_etl_dag
AIRFLOW_CTX_TASK_ID=load_data
AIRFLOW_CTX_EXECUTION_DATE=2021-09-07T01:16:30.724298+00:00
AIRFLOW_CTX_DAG_RUN_ID=manual__2021-09-07T01:16:30.724298+00:00
[2021-09-07 01:16:32,513] {base.py:70} INFO - Using connection to: id: PostgreSQL 13. Host: localhost, Port: 5432, Schema: hoverstate, Login: ***, Password: ***, extra: {}
[2021-09-07 01:16:32,514] {taskinstance.py:1462} ERROR - Task failed with exception
Traceback (most recent call last):
  File "/home/airflow/.local/lib/python3.8/site-packages/airflow/models/taskinstance.py", line 1164, in _run_raw_task
    self._prepare_and_execute_task_with_callbacks(context, task)
  File "/home/airflow/.local/lib/python3.8/site-packages/airflow/models/taskinstance.py", line 1282, in _prepare_and_execute_task_with_callbacks
    result = self._execute_task(context, task_copy)
  File "/home/airflow/.local/lib/python3.8/site-packages/airflow/models/taskinstance.py", line 1312, in _execute_task
    result = task_copy.execute(context=context)
  File "/home/airflow/.local/lib/python3.8/site-packages/airflow/operators/python.py", line 150, in execute
    return_value = self.execute_callable()
  File "/home/airflow/.local/lib/python3.8/site-packages/airflow/operators/python.py", line 161, in execute_callable
    return self.python_callable(*self.op_args, **self.op_kwargs)
  File "/opt/airflow/dags/hoverstate_etl.py", line 90, in load_data
    execute_load(pg_hook, "users", users_path)
  File "/opt/airflow/dags/hoverstate_etl.py", line 150, in execute_load
    pg_hook.copy_expert(query, file_path)
  File "/home/airflow/.local/lib/python3.8/site-packages/airflow/providers/postgres/hooks/postgres.py", line 134, in copy_expert
    with closing(self.get_conn()) as conn:
  File "/home/airflow/.local/lib/python3.8/site-packages/airflow/providers/postgres/hooks/postgres.py", line 115, in get_conn
    self.conn = psycopg2.connect(**conn_args)
  File "/home/airflow/.local/lib/python3.8/site-packages/psycopg2/__init__.py", line 122, in connect
    conn = _connect(dsn, connection_factory=connection_factory, **kwasync)
psycopg2.OperationalError: could not connect to server: Connection refused
	Is the server running on host "localhost" (127.0.0.1) and accepting
	TCP/IP connections on port 5432?
could not connect to server: Cannot assign requested address
	Is the server running on host "localhost" (::1) and accepting
	TCP/IP connections on port 5432?

[2021-09-07 01:16:32,515] {taskinstance.py:1505} INFO - Marking task as FAILED. dag_id=users_and_posts_etl_dag, task_id=load_data, execution_date=20210907T011630, start_date=20210907T011632, end_date=20210907T011632
[2021-09-07 01:16:32,554] {local_task_job.py:151} INFO - Task exited with return code 1
[2021-09-07 01:16:32,574] {local_task_job.py:261} INFO - 0 downstream tasks scheduled from follow-on schedule check
