[2021-09-07 00:00:00,417] {taskinstance.py:903} INFO - Dependencies all met for <TaskInstance: users_and_posts_etl_dag.load_data 2021-09-06T00:00:00+00:00 [queued]>
[2021-09-07 00:00:00,430] {taskinstance.py:903} INFO - Dependencies all met for <TaskInstance: users_and_posts_etl_dag.load_data 2021-09-06T00:00:00+00:00 [queued]>
[2021-09-07 00:00:00,430] {taskinstance.py:1094} INFO - 
--------------------------------------------------------------------------------
[2021-09-07 00:00:00,430] {taskinstance.py:1095} INFO - Starting attempt 1 of 1
[2021-09-07 00:00:00,430] {taskinstance.py:1096} INFO - 
--------------------------------------------------------------------------------
[2021-09-07 00:00:00,438] {taskinstance.py:1114} INFO - Executing <Task(PythonOperator): load_data> on 2021-09-06T00:00:00+00:00
[2021-09-07 00:00:00,441] {standard_task_runner.py:52} INFO - Started process 27391 to run task
[2021-09-07 00:00:00,446] {standard_task_runner.py:76} INFO - Running: ['***', 'tasks', 'run', 'users_and_posts_etl_dag', 'load_data', '2021-09-06T00:00:00+00:00', '--job-id', '31', '--pool', 'default_pool', '--raw', '--subdir', 'DAGS_FOLDER/hoverstate_etl.py', '--cfg-path', '/tmp/tmp5tvb0_nf', '--error-file', '/tmp/tmp2zqmaag3']
[2021-09-07 00:00:00,446] {standard_task_runner.py:77} INFO - Job 31: Subtask load_data
[2021-09-07 00:00:00,481] {logging_mixin.py:109} INFO - Running <TaskInstance: users_and_posts_etl_dag.load_data 2021-09-06T00:00:00+00:00 [running]> on host 731700afc5ff
[2021-09-07 00:00:00,525] {taskinstance.py:1251} INFO - Exporting the following env vars:
AIRFLOW_CTX_DAG_OWNER=***
AIRFLOW_CTX_DAG_ID=users_and_posts_etl_dag
AIRFLOW_CTX_TASK_ID=load_data
AIRFLOW_CTX_EXECUTION_DATE=2021-09-06T00:00:00+00:00
AIRFLOW_CTX_DAG_RUN_ID=scheduled__2021-09-06T00:00:00+00:00
[2021-09-07 00:00:00,526] {logging_mixin.py:109} INFO - <TaskInstance: users_and_posts_etl_dag.load_data 2021-09-06T00:00:00+00:00 [running]>
[2021-09-07 00:00:00,539] {logging_mixin.py:109} INFO - None
[2021-09-07 00:00:00,539] {logging_mixin.py:109} INFO - None
[2021-09-07 00:00:00,539] {taskinstance.py:1462} ERROR - Task failed with exception
Traceback (most recent call last):
  File "/home/airflow/.local/lib/python3.8/site-packages/airflow/models/taskinstance.py", line 1164, in _run_raw_task
    self._prepare_and_execute_task_with_callbacks(context, task)
  File "/home/airflow/.local/lib/python3.8/site-packages/airflow/models/taskinstance.py", line 1282, in _prepare_and_execute_task_with_callbacks
    result = self._execute_task(context, task_copy)
  File "/home/airflow/.local/lib/python3.8/site-packages/airflow/models/taskinstance.py", line 1312, in _execute_task
    result = task_copy.execute(context=context)
  File "/home/airflow/.local/lib/python3.8/site-packages/airflow/operators/python.py", line 150, in execute
    return_value = self.execute_callable()
  File "/home/airflow/.local/lib/python3.8/site-packages/airflow/operators/python.py", line 161, in execute_callable
    return self.python_callable(*self.op_args, **self.op_kwargs)
  File "/opt/airflow/dags/hoverstate_etl.py", line 51, in load_data
    for user in users_data:
TypeError: 'NoneType' object is not iterable
[2021-09-07 00:00:00,541] {taskinstance.py:1505} INFO - Marking task as FAILED. dag_id=users_and_posts_etl_dag, task_id=load_data, execution_date=20210906T000000, start_date=20210907T000000, end_date=20210907T000000
[2021-09-07 00:00:00,578] {local_task_job.py:151} INFO - Task exited with return code 1
[2021-09-07 00:00:00,599] {local_task_job.py:261} INFO - 0 downstream tasks scheduled from follow-on schedule check
