[2021-09-07 04:09:12,376] {taskinstance.py:903} INFO - Dependencies all met for <TaskInstance: users_and_posts_etl_dag.load_data 2021-09-07T04:09:10.778861+00:00 [queued]>
[2021-09-07 04:09:12,386] {taskinstance.py:903} INFO - Dependencies all met for <TaskInstance: users_and_posts_etl_dag.load_data 2021-09-07T04:09:10.778861+00:00 [queued]>
[2021-09-07 04:09:12,386] {taskinstance.py:1094} INFO - 
--------------------------------------------------------------------------------
[2021-09-07 04:09:12,387] {taskinstance.py:1095} INFO - Starting attempt 1 of 1
[2021-09-07 04:09:12,387] {taskinstance.py:1096} INFO - 
--------------------------------------------------------------------------------
[2021-09-07 04:09:12,398] {taskinstance.py:1114} INFO - Executing <Task(PythonOperator): load_data> on 2021-09-07T04:09:10.778861+00:00
[2021-09-07 04:09:12,401] {standard_task_runner.py:52} INFO - Started process 19344 to run task
[2021-09-07 04:09:12,403] {standard_task_runner.py:76} INFO - Running: ['***', 'tasks', 'run', 'users_and_posts_etl_dag', 'load_data', '2021-09-07T04:09:10.778861+00:00', '--job-id', '180', '--pool', 'default_pool', '--raw', '--subdir', 'DAGS_FOLDER/hoverstate_etl.py', '--cfg-path', '/tmp/tmp7j6v8wg8', '--error-file', '/tmp/tmp4vgylbqe']
[2021-09-07 04:09:12,403] {standard_task_runner.py:77} INFO - Job 180: Subtask load_data
[2021-09-07 04:09:12,433] {logging_mixin.py:109} INFO - Running <TaskInstance: users_and_posts_etl_dag.load_data 2021-09-07T04:09:10.778861+00:00 [running]> on host 731700afc5ff
[2021-09-07 04:09:12,483] {taskinstance.py:1251} INFO - Exporting the following env vars:
AIRFLOW_CTX_DAG_OWNER=***
AIRFLOW_CTX_DAG_ID=users_and_posts_etl_dag
AIRFLOW_CTX_TASK_ID=load_data
AIRFLOW_CTX_EXECUTION_DATE=2021-09-07T04:09:10.778861+00:00
AIRFLOW_CTX_DAG_RUN_ID=manual__2021-09-07T04:09:10.778861+00:00
[2021-09-07 04:09:12,507] {base.py:70} INFO - Using connection to: id: nickel-aws. Host: nickel.caybmxchvlv1.us-east-1.rds.amazonaws.com, Port: 5432, Schema: , Login: postgres, Password: ***, extra: {}
[2021-09-07 04:09:13,467] {base.py:70} INFO - Using connection to: id: nickel-aws. Host: nickel.caybmxchvlv1.us-east-1.rds.amazonaws.com, Port: 5432, Schema: , Login: postgres, Password: ***, extra: {}
[2021-09-07 04:09:14,282] {taskinstance.py:1462} ERROR - Task failed with exception
Traceback (most recent call last):
  File "/home/airflow/.local/lib/python3.8/site-packages/airflow/models/taskinstance.py", line 1164, in _run_raw_task
    self._prepare_and_execute_task_with_callbacks(context, task)
  File "/home/airflow/.local/lib/python3.8/site-packages/airflow/models/taskinstance.py", line 1282, in _prepare_and_execute_task_with_callbacks
    result = self._execute_task(context, task_copy)
  File "/home/airflow/.local/lib/python3.8/site-packages/airflow/models/taskinstance.py", line 1312, in _execute_task
    result = task_copy.execute(context=context)
  File "/home/airflow/.local/lib/python3.8/site-packages/airflow/operators/python.py", line 150, in execute
    return_value = self.execute_callable()
  File "/home/airflow/.local/lib/python3.8/site-packages/airflow/operators/python.py", line 161, in execute_callable
    return self.python_callable(*self.op_args, **self.op_kwargs)
  File "/opt/airflow/dags/hoverstate_etl.py", line 91, in load_data
    execute_load(pg_hook, "posts", posts_path)
  File "/opt/airflow/dags/hoverstate_etl.py", line 98, in execute_load
    pg_hook.copy_expert(query, file_path)
  File "/home/airflow/.local/lib/python3.8/site-packages/airflow/providers/postgres/hooks/postgres.py", line 136, in copy_expert
    cur.copy_expert(sql, file)
psycopg2.errors.InvalidTextRepresentation: invalid input syntax for type integer: "suscipit recusandae consequuntur expedita et cum"
CONTEXT:  COPY posts, line 2, column id: "suscipit recusandae consequuntur expedita et cum"

[2021-09-07 04:09:14,284] {taskinstance.py:1505} INFO - Marking task as FAILED. dag_id=users_and_posts_etl_dag, task_id=load_data, execution_date=20210907T040910, start_date=20210907T040912, end_date=20210907T040914
[2021-09-07 04:09:14,300] {local_task_job.py:151} INFO - Task exited with return code 1
[2021-09-07 04:09:14,319] {local_task_job.py:261} INFO - 0 downstream tasks scheduled from follow-on schedule check
