[2021-09-07 05:44:00,458] {taskinstance.py:903} INFO - Dependencies all met for <TaskInstance: json_etl_dag.load_data 2021-09-07T05:43:57.139735+00:00 [queued]>
[2021-09-07 05:44:00,466] {taskinstance.py:903} INFO - Dependencies all met for <TaskInstance: json_etl_dag.load_data 2021-09-07T05:43:57.139735+00:00 [queued]>
[2021-09-07 05:44:00,466] {taskinstance.py:1094} INFO - 
--------------------------------------------------------------------------------
[2021-09-07 05:44:00,466] {taskinstance.py:1095} INFO - Starting attempt 1 of 1
[2021-09-07 05:44:00,467] {taskinstance.py:1096} INFO - 
--------------------------------------------------------------------------------
[2021-09-07 05:44:00,477] {taskinstance.py:1114} INFO - Executing <Task(PythonOperator): load_data> on 2021-09-07T05:43:57.139735+00:00
[2021-09-07 05:44:00,480] {standard_task_runner.py:52} INFO - Started process 28570 to run task
[2021-09-07 05:44:00,483] {standard_task_runner.py:76} INFO - Running: ['***', 'tasks', 'run', 'json_etl_dag', 'load_data', '2021-09-07T05:43:57.139735+00:00', '--job-id', '207', '--pool', 'default_pool', '--raw', '--subdir', 'DAGS_FOLDER/etl.py', '--cfg-path', '/tmp/tmpu0ywv2ks', '--error-file', '/tmp/tmpnuydrgn4']
[2021-09-07 05:44:00,483] {standard_task_runner.py:77} INFO - Job 207: Subtask load_data
[2021-09-07 05:44:00,512] {logging_mixin.py:109} INFO - Running <TaskInstance: json_etl_dag.load_data 2021-09-07T05:43:57.139735+00:00 [running]> on host 731700afc5ff
[2021-09-07 05:44:00,552] {taskinstance.py:1251} INFO - Exporting the following env vars:
AIRFLOW_CTX_DAG_OWNER=***
AIRFLOW_CTX_DAG_ID=json_etl_dag
AIRFLOW_CTX_TASK_ID=load_data
AIRFLOW_CTX_EXECUTION_DATE=2021-09-07T05:43:57.139735+00:00
AIRFLOW_CTX_DAG_RUN_ID=manual__2021-09-07T05:43:57.139735+00:00
[2021-09-07 05:44:00,575] {base.py:70} INFO - Using connection to: id: nickel-aws. Host: nickel.caybmxchvlv1.us-east-1.rds.amazonaws.com, Port: 5432, Schema: , Login: postgres, Password: ***, extra: {}
[2021-09-07 05:44:01,128] {base.py:70} INFO - Using connection to: id: nickel-aws. Host: nickel.caybmxchvlv1.us-east-1.rds.amazonaws.com, Port: 5432, Schema: , Login: postgres, Password: ***, extra: {}
[2021-09-07 05:44:02,253] {taskinstance.py:1462} ERROR - Task failed with exception
Traceback (most recent call last):
  File "/home/airflow/.local/lib/python3.8/site-packages/airflow/models/taskinstance.py", line 1164, in _run_raw_task
    self._prepare_and_execute_task_with_callbacks(context, task)
  File "/home/airflow/.local/lib/python3.8/site-packages/airflow/models/taskinstance.py", line 1282, in _prepare_and_execute_task_with_callbacks
    result = self._execute_task(context, task_copy)
  File "/home/airflow/.local/lib/python3.8/site-packages/airflow/models/taskinstance.py", line 1312, in _execute_task
    result = task_copy.execute(context=context)
  File "/home/airflow/.local/lib/python3.8/site-packages/airflow/operators/python.py", line 150, in execute
    return_value = self.execute_callable()
  File "/home/airflow/.local/lib/python3.8/site-packages/airflow/operators/python.py", line 161, in execute_callable
    return self.python_callable(*self.op_args, **self.op_kwargs)
  File "/opt/airflow/dags/etl.py", line 100, in load_data
    execute_load(pg_hook, "users", users_path)
  File "/opt/airflow/dags/etl.py", line 110, in execute_load
    pg_hook.copy_expert(import_query, file_path)
  File "/home/airflow/.local/lib/python3.8/site-packages/airflow/providers/postgres/hooks/postgres.py", line 136, in copy_expert
    cur.copy_expert(sql, file)
psycopg2.errors.UndefinedTable: relation "users_temp" does not exist

[2021-09-07 05:44:02,255] {taskinstance.py:1505} INFO - Marking task as FAILED. dag_id=json_etl_dag, task_id=load_data, execution_date=20210907T054357, start_date=20210907T054400, end_date=20210907T054402
[2021-09-07 05:44:02,301] {local_task_job.py:151} INFO - Task exited with return code 1
[2021-09-07 05:44:02,323] {local_task_job.py:261} INFO - 0 downstream tasks scheduled from follow-on schedule check
