[2021-09-07 05:21:48,911] {taskinstance.py:903} INFO - Dependencies all met for <TaskInstance: users_and_posts_etl_dag.load_data 2021-09-07T05:21:47.079255+00:00 [queued]>
[2021-09-07 05:21:48,920] {taskinstance.py:903} INFO - Dependencies all met for <TaskInstance: users_and_posts_etl_dag.load_data 2021-09-07T05:21:47.079255+00:00 [queued]>
[2021-09-07 05:21:48,920] {taskinstance.py:1094} INFO - 
--------------------------------------------------------------------------------
[2021-09-07 05:21:48,920] {taskinstance.py:1095} INFO - Starting attempt 1 of 1
[2021-09-07 05:21:48,920] {taskinstance.py:1096} INFO - 
--------------------------------------------------------------------------------
[2021-09-07 05:21:48,931] {taskinstance.py:1114} INFO - Executing <Task(PythonOperator): load_data> on 2021-09-07T05:21:47.079255+00:00
[2021-09-07 05:21:48,934] {standard_task_runner.py:52} INFO - Started process 26394 to run task
[2021-09-07 05:21:48,936] {standard_task_runner.py:76} INFO - Running: ['***', 'tasks', 'run', 'users_and_posts_etl_dag', 'load_data', '2021-09-07T05:21:47.079255+00:00', '--job-id', '194', '--pool', 'default_pool', '--raw', '--subdir', 'DAGS_FOLDER/etl.py', '--cfg-path', '/tmp/tmp2m1wf3q6', '--error-file', '/tmp/tmpjizzvrjr']
[2021-09-07 05:21:48,936] {standard_task_runner.py:77} INFO - Job 194: Subtask load_data
[2021-09-07 05:21:48,968] {logging_mixin.py:109} INFO - Running <TaskInstance: users_and_posts_etl_dag.load_data 2021-09-07T05:21:47.079255+00:00 [running]> on host 731700afc5ff
[2021-09-07 05:21:49,010] {taskinstance.py:1251} INFO - Exporting the following env vars:
AIRFLOW_CTX_DAG_OWNER=***
AIRFLOW_CTX_DAG_ID=users_and_posts_etl_dag
AIRFLOW_CTX_TASK_ID=load_data
AIRFLOW_CTX_EXECUTION_DATE=2021-09-07T05:21:47.079255+00:00
AIRFLOW_CTX_DAG_RUN_ID=manual__2021-09-07T05:21:47.079255+00:00
[2021-09-07 05:21:49,034] {base.py:70} INFO - Using connection to: id: nickel-aws. Host: nickel.caybmxchvlv1.us-east-1.rds.amazonaws.com, Port: 5432, Schema: , Login: postgres, Password: ***, extra: {}
[2021-09-07 05:21:49,574] {taskinstance.py:1462} ERROR - Task failed with exception
Traceback (most recent call last):
  File "/home/airflow/.local/lib/python3.8/site-packages/airflow/models/taskinstance.py", line 1164, in _run_raw_task
    self._prepare_and_execute_task_with_callbacks(context, task)
  File "/home/airflow/.local/lib/python3.8/site-packages/airflow/models/taskinstance.py", line 1282, in _prepare_and_execute_task_with_callbacks
    result = self._execute_task(context, task_copy)
  File "/home/airflow/.local/lib/python3.8/site-packages/airflow/models/taskinstance.py", line 1312, in _execute_task
    result = task_copy.execute(context=context)
  File "/home/airflow/.local/lib/python3.8/site-packages/airflow/operators/python.py", line 150, in execute
    return_value = self.execute_callable()
  File "/home/airflow/.local/lib/python3.8/site-packages/airflow/operators/python.py", line 161, in execute_callable
    return self.python_callable(*self.op_args, **self.op_kwargs)
  File "/opt/airflow/dags/etl.py", line 99, in load_data
    execute_load(pg_hook, "users", users_path)
  File "/opt/airflow/dags/etl.py", line 107, in execute_load
    cusros.execute(temp_query)
NameError: name 'cusros' is not defined
[2021-09-07 05:21:49,576] {taskinstance.py:1505} INFO - Marking task as FAILED. dag_id=users_and_posts_etl_dag, task_id=load_data, execution_date=20210907T052147, start_date=20210907T052148, end_date=20210907T052149
[2021-09-07 05:21:49,630] {local_task_job.py:151} INFO - Task exited with return code 1
[2021-09-07 05:21:49,650] {local_task_job.py:261} INFO - 0 downstream tasks scheduled from follow-on schedule check
